<?xml version="1.0"?>
<robot xmlns:xacro="http://ros.org/wiki/xacro">

<!--
  Author: Su yu
-->
<xacro:arg name="use_effort_interface" default="false" />

<xacro:include filename="$(find oarm3)/urdf/oarm3.transmission.xacro" />
 <xacro:include filename="$(find oarm3)/urdf/oarm3.gazebo.xacro" />
 <xacro:include filename="$(find oarm3)/urdf/oarm3_matrix.xacro" />

  <xacro:macro name="oarm3"  params="prefix joint_limited
    shoulder_1_lower_limit="${-pi}" shoulder_1_upper_limit="${pi}"
    shoulder_2_lower_limit="${-pi}" shoulder_2_upper_limit="${pi}"
    shouldel_lift_lower_limit="${-pi}" shoulder_lift_upper_limit="${pi}"
    elbow_joint_lower_limit="${-pi}" elbow_joint_upper_limit="${pi}"
    wrist_1_lower_limit="${-pi}" wrist_1_upper_limit="${pi}"
    wrist_2_lower_limit="${-pi}" wrist_2_upper_limit="${pi}"
    wrist_3_lower_limit="${-pi}" wrist_3_upper_limit="${pi}""
  />
<!--//////////////////////////////////////////////////////////////////////////////////////////////-->
<!-- Inertia parameters -->
    <xacro:property name="base_mass" value="2.0" />  <!-- This mass might be incorrect -->
    <xacro:property name="shoulder_mass" value="2.0" />
    <xacro:property name="upper_arm_mass" value="3.42" />
    <xacro:property name="forearm_mass" value="1.26" />
    <xacro:property name="wrist_1_mass" value="0.8" />
    <xacro:property name="wrist_2_mass" value="0.8" />
    <xacro:property name="wrist_3_mass" value="0.35" />
    <xacro:macro name="link1 matrix" mass="191.26"/>
    <xacro:macro name="link2 matrix" mass="163.16"/>
    <xacro:macro name="link3 matrix" mass="687.93"/>
    <xacro:macro name="link4 matrix" mass="702.78"/>
    <xacro:macro name="link5 matrix" mass="161.51"/>
    <xacro:macro name="link6 matrix" mass="180.11"/>
    <xacro:macro name="link7 matrix" mass="106.09"/>

<material name="LightGrey">
        <color rgba="0.7 0.7 0.7 1.0"/>
    </material>

<!--////////////////////////////////////////////////////////////////        base_link       //////////////////////////////////////////////////////////////// -->
    <link name="${prefix}base_link" >
      <visual>
        <geometry>
          <mesh filename="package://oarm3/meshes/base_link.STL"/>
        </geometry>
        <material name="LightGrey"/>
      </visual>

      <collision>
        <geometry>
          <mesh filename="package://ur_description/meshes/ur3/collision/base.stl"/>
        </geometry>
      </collision>
      
      
      <xacro:macro name="base_link matrix" mass="14.303" />>
    </link>

<!--////////////////////////////////////////////////////////////////        shoulder_1_joint       //////////////////////////////////////////////////////////////// -->
    <joint name="${prefix}shoulder_1_joint" type="revolute">
      <parent link="${prefix}base_link" />
      <child link = "${prefix}shoulder_link" />
      <origin xyz="0.0 0.0 ${shoulder_height}" rpy="0.0 0.0 0.0" />
      <axis xyz="0 0 1" />
      <xacro:unless value="${joint_limited}">
        <limit lower="${-2.0 * pi}" upper="${2.0 * pi}" effort="330.0" velocity="2.16"/>
      </xacro:unless>
      <xacro:if value="${joint_limited}">
        <limit lower="${shoulder_1_lower_limit}" upper="${shoulder_1_upper_limit}" effort="330.0" velocity="2.16"/>
      </xacro:if>
      <dynamics damping="0.0" friction="0.0"/>
    </joint>

<!--////////////////////////////////////////////////////////////////        shoulder_1_link       //////////////////////////////////////////////////////////////// -->
    <link name="${prefix}shoulder_1_link">
      <visual>
        <geometry>
          <mesh filename="package://oarm3/meshes/link1.STL"/>
        </geometry>
        <material name="LightGrey"/>
          
      </visual>
      
      <collision>
        <geometry>
          <mesh filename="package://oarm3/meshes/link1.STL"/>
        </geometry>
      </collision>

      <xacro:cylinder_inertial radius="0.075" length="0.178" mass="${shoulder_mass}">
        <origin xyz="0.0 0.0 0.0" rpy="0 0 0" />
      </xacro:cylinder_inertial>
    </link>

<!--////////////////////////////////////////////////////////////////        shoulder_2_joint       //////////////////////////////////////////////////////////////// -->
    <joint name="${prefix}shoulder_2_joint" type="revolute">
      <parent link="${prefix}shoulder_1_link" />
      <child link = "${prefix}shoulder_2_link" />
      <origin xyz="0.0 0.0 ${shoulder_height}" rpy="0.0 0.0 0.0" />
      <axis xyz="0 0 1" />
      <xacro:unless value="${joint_limited}">
        <limit lower="${-2.0 * pi}" upper="${2.0 * pi}" effort="330.0" velocity="2.16"/>
      </xacro:unless>
      <xacro:if value="${joint_limited}">
        <limit lower="${shoulder_1_lower_limit}" upper="${shoulder_1_upper_limit}" effort="330.0" velocity="2.16"/>
      </xacro:if>
      <dynamics damping="0.0" friction="0.0"/>
    </joint>

<!--////////////////////////////////////////////////////////////////        shoulder_2_link       //////////////////////////////////////////////////////////////// -->
    <link name="${prefix}shoulder_2_link">
      <visual>
        <geometry>
          <mesh filename="package://oarm3/meshes/link2.STL"/>
        </geometry>
        <material name="LightGrey"/>
          
      </visual>
      
      <collision>
        <geometry>
          <mesh filename="package://oarm3/meshes/link2.STL"/>
        </geometry>
      </collision>

      <xacro:cylinder_inertial radius="0.075" length="0.178" mass="${shoulder_mass}">
        <origin xyz="0.0 0.0 0.0" rpy="0 0 0" />
      </xacro:cylinder_inertial>
    </link>

<!--////////////////////////////////////////////////////////////////        shoulder_lift_joint       //////////////////////////////////////////////////////////////// -->
<joint name="${prefix}shoulder_lift_joint" type="revolute">
      <parent link="${prefix}shoulder_link" />
      <child link = "${prefix}upper_arm_link" />
      <origin xyz="0.0 ${shoulder_offset} 0.0" rpy="0.0 ${pi / 2.0} 0.0" />
      <axis xyz="0 1 0" />
      <xacro:unless value="${joint_limited}">
        <limit lower="${-2.0 * pi}" upper="${2.0 * pi}" effort="330.0" velocity="2.16"/>
      </xacro:unless>
      <xacro:if value="${joint_limited}">
        <limit lower="${shoulder_lift_lower_limit}" upper="${shoulder_lift_upper_limit}" effort="330.0" velocity="2.16"/>
      </xacro:if>
      <dynamics damping="0.0" friction="0.0"/>
    </joint>

    <!--////////////////////////////////////////////////////////////////        upper_arm_link       //////////////////////////////////////////////////////////////// -->
    <link name="${prefix}upper_arm_link">
      <visual>
        <geometry>
          <mesh filename="package://oarm3/meshes/link3.STL"/>
        </geometry>
        <material name="LightGrey">
          <color rgba="0.7 0.7 0.7 1.0"/>
        </material>
      </visual>
      <collision>
        <geometry>
          <mesh filename="package://oarm3/meshes/link3.STL"/>
        </geometry>
      </collision>
      <xacro:cylinder_inertial radius="0.075" length="${-a2}" mass="${upper_arm_mass}">
        <origin xyz="0.0 0.0 ${-a2/2.0}" rpy="0 0 0" />
      </xacro:cylinder_inertial>
    </link>

<!--////////////////////////////////////////////////////////////////        elbow_joint       //////////////////////////////////////////////////////////////// -->
<joint name="${prefix}elbow_joint" type="revolute">
      <parent link="${prefix}upper_arm_link" />
      <child link = "${prefix}forearm_link" />
      <origin xyz="0.0 ${elbow_offset} ${upper_arm_length}" rpy="0.0 0.0 0.0" />
      <axis xyz="0 1 0" />
      <xacro:unless value="${joint_limited}">
        <limit lower="${-pi}" upper="${pi}" effort="150.0" velocity="3.15"/>
      </xacro:unless>
      <xacro:if value="${joint_limited}">
        <limit lower="${elbow_joint_lower_limit}" upper="${elbow_joint_upper_limit}" effort="150.0" velocity="3.15"/>
      </xacro:if>
      <dynamics damping="0.0" friction="0.0"/>
    </joint>

    <!--////////////////////////////////////////////////////////////////       forearm_link        //////////////////////////////////////////////////////////////// -->
    <link name="${prefix}forearm_link">
      <visual>
         <geometry>
          <mesh filename="package://oarm3/meshes/link4.STL"/>
        </geometry>
        <material name="LightGrey">
          <color rgba="0.7 0.7 0.7 1.0"/>
        </material>
      </visual>
      <collision>
        <geometry>
          <mesh filename="package://oarm3/meshes/link4.STL"/>
        </geometry>
      </collision>
      <xacro:cylinder_inertial radius="0.075" length="${-a3}" mass="${forearm_mass}">
        <origin xyz="0.0 0.0 ${-a3/2.0}" rpy="0 0 0" />
      </xacro:cylinder_inertial>
    </link>

<!--////////////////////////////////////////////////////////////////       wrist_1_joint        //////////////////////////////////////////////////////////////// -->
    <joint name="${prefix}wrist_1_joint" type="revolute">
      <parent link="${prefix}forearm_link" />
      <child link = "${prefix}wrist_1_link" />
      <origin xyz="0.0 0.0 ${forearm_length}" rpy="0.0 ${pi / 2.0} 0.0" />
      <axis xyz="0 1 0" />
      <xacro:unless value="${joint_limited}">
        <limit lower="${-2.0 * pi}" upper="${2.0 * pi}" effort="54.0" velocity="3.2"/>
      </xacro:unless>
      <xacro:if value="${joint_limited}">
        <limit lower="${wrist_1_lower_limit}" upper="${wrist_1_upper_limit}" effort="54.0" velocity="3.2"/>
      </xacro:if>
      <dynamics damping="0.0" friction="0.0"/>
    </joint>

<!--////////////////////////////////////////////////////////////////       wrist1_link        //////////////////////////////////////////////////////////////// -->
    <link name="${prefix}wrist_1_link">
      <visual>
        <geometry>
          <mesh filename="package://oarm3/meshes/link5.STL"/>
        </geometry>
        <material name="LightGrey">
          <color rgba="0.7 0.7 0.7 1.0"/>
        </material>
      </visual>
      <collision>
        <geometry>
          <mesh filename="package://oarm3/meshes/link5.STL"/>
        </geometry>
      </collision>
      <xacro:cylinder_inertial radius="0.075" length="0.12" mass="${wrist_1_mass}">
        <origin xyz="0.0 0.0 0.0" rpy="0 0 0" />
      </xacro:cylinder_inertial>
    </link>

<!--////////////////////////////////////////////////////////////////       wrist_2_joint        //////////////////////////////////////////////////////////////// -->
    <joint name="${prefix}wrist_2_joint" type="revolute">
      <parent link="${prefix}wrist_1_link" />
      <child link = "${prefix}wrist_2_link" />
      <origin xyz="0.0 ${wrist1_length} 0.0" rpy="0.0 0.0 0.0" />
      <axis xyz="0 0 1" />
      <xacro:unless value="${joint_limited}">
        <limit lower="${-2.0 * pi}" upper="${2.0 * pi}" effort="54.0" velocity="3.2"/>
      </xacro:unless>
      <xacro:if value="${joint_limited}">
        <limit lower="${wrist_2_lower_limit}" upper="${wrist_2_upper_limit}" effort="54.0" velocity="3.2"/>
      </xacro:if>
      <dynamics damping="0.0" friction="0.0"/>
    </joint>

    <!--////////////////////////////////////////////////////////////////       wrist2_link        //////////////////////////////////////////////////////////////// -->
    <link name="${prefix}wrist_2_link">
      <visual>
        <geometry>
          <mesh filename="package://oarm3/meshes/link6.STL"/>
        </geometry>
        <material name="LightGrey">
          <color rgba="0.7 0.7 0.7 1.0"/>
        </material>
      </visual>
      <collision>
        <geometry>
          <mesh filename="package://oarm3/meshes/link6.STL"/>
        </geometry>
      </collision>
      <xacro:cylinder_inertial radius="0.075" length="0.12" mass="${wrist_2_mass}">
        <origin xyz="0.0 0.0 0.0" rpy="0 0 0" />
      </xacro:cylinder_inertial>
    </link>

<!--////////////////////////////////////////////////////////////////       wrist_3_joint        //////////////////////////////////////////////////////////////// -->
<joint name="${prefix}wrist_3_joint" type="revolute">
      <parent link="${prefix}wrist_2_link" />
      <child link = "${prefix}wrist_3_link" />
      <origin xyz="0.0 0.0 ${wrist_2_length}" rpy="0.0 0.0 0.0" />
      <axis xyz="0 1 0" />
      <xacro:unless value="${joint_limited}">
        <limit lower="${-2.0 * pi}" upper="${2.0 * pi}" effort="54.0" velocity="3.2"/>
      </xacro:unless>
      <xacro:if value="${joint_limited}">
        <limit lower="${wrist_3_lower_limit}" upper="${wrist_3_upper_limit}" effort="54.0" velocity="3.2"/>
      </xacro:if>
      <dynamics damping="0.0" friction="0.0"/>
    </joint>

    <!--////////////////////////////////////////////////////////////////       wrist_3_link        //////////////////////////////////////////////////////////////// -->
    <link name="${prefix}wrist_3_link">
      <visual>
        <geometry>
          <mesh filename="package://oarm3/meshes/link7.STL"/>
        </geometry>
        <material name="LightGrey">
          <color rgba="0.7 0.7 0.7 1.0"/>
        </material>
      </visual>
      <collision>
        <geometry>
          <mesh filename="package://oarm3/meshes/link7.STL"/>
        </geometry>
      </collision>
      <xacro:cylinder_inertial radius="0.075" length="0.12" mass="${wrist_3_mass}">
        <origin xyz="0.0 0.0 0.0" rpy="0 0 0" />
      </xacro:cylinder_inertial>
    </link>